Workbook
Name CARREAUX_S1: Parametres!$C$106
Name CHAUX_M2_KG: Parametres!$C$102
Name CHEVRON_TRAV_V1: Parametres!$C$86
Name CIMENT_COLLE_KGM2: Parametres!$C$104
Name CLOUS_CHARPENTE_KGM3: Parametres!$C$94
Name CLOUS_COFFRAGE_KGM2: Parametres!$C$93
Name CLOUS_COUVERTURE_KGM2: Parametres!$C$95
Name COEF_GRAVIER_VOL: Parametres!$C$11
Name COEF_SABLE_MORTIER: Parametres!$C$18
Name COEF_SABLE_VOL: Parametres!$C$13
Name CROCHET: Parametres!$C$54
Name CT_TASSEMENT: Parametres!$C$74
Name DENSITE_BETON_FRAIS: Parametres!$C$78
Name DENSITE_GRAVIER: Parametres!$C$12
Name DENSITE_MOELLON: Parametres!$C$76
Name DENSITE_SABLE: Parametres!$C$14
Name DENSITE_TERRE: Parametres!$C$79
Name DOSAGE_MORTIER_MACONNERIE: Parametres!$C$22
Name EAU_PAR_DOSAGE: Parametres!$C$16
Name ENDUIT_CIMENT_KGM2: Parametres!$C$99
Name ENROBAGE: Parametres!$C$53
Name FAIENCE_S1: Parametres!$C$107
Name FIL_LIGATURE_PCT: Parametres!$C$55
Name JOINT_MACONNERIE: Parametres!$C$23
Name LONG_BARRE_COMMERCIALE: Parametres!$C$51
Name LONG_BARRE_UTILE: Parametres!$C$52
Name MAJORATION_ACHAT: Parametres!$C$75
Name MAJORATION_CARRELAGE: Parametres!$C$108
Name MOELLON_PCT_VOLUME: Parametres!$C$77
Name NB_COUCHES_PEINTURE: Parametres!$C$103
Name NUANCE_HA_DEFAUT: Parametres!$C$67
Name NUANCE_RL_DEFAUT: Parametres!$C$68
Name PEINTURE_CLASSIQUE_M2_L: Parametres!$C$101
Name PEINTURE_LATEX_M2_KG: Parametres!$C$100
Name PLANCHE_e: Parametres!$C$85
Name PLANCHE_L: Parametres!$C$83
Name PLANCHE_LARGEUR: Parametres!$C$84
Name POIDS_SAC_CIMENT: Parametres!$C$10
Name POIDS_VOL_ACIER: Parametres!$C$56
Name PU_AMENEE_REPLI: Prix_Unitaires!$D$75
Name PU_BLOC15: Prix_Unitaires!$D$41
Name PU_BLOC20: Prix_Unitaires!$D$42
Name PU_CARREAUX: Prix_Unitaires!$D$54
Name PU_CHAUX: Prix_Unitaires!$D$51
Name PU_CHEVRON: Prix_Unitaires!$D$39
Name PU_CIMENT: Prix_Unitaires!$D$10
Name PU_CIMENTCOLLE: Prix_Unitaires!$D$50
Name PU_CLOUS: Prix_Unitaires!$D$40
Name PU_DRESSEMENT_TABLEAUX: Prix_Unitaires!$D$85
Name PU_EAU: Prix_Unitaires!$D$14
Name PU_EVACUATION_DEBLAIS: Prix_Unitaires!$D$80
Name PU_FAIENCE: Prix_Unitaires!$D$55
Name PU_FIL: Prix_Unitaires!$D$33
Name PU_FORME_PENTE: Prix_Unitaires!$D$86
Name PU_FOUILLE_PUITS: Prix_Unitaires!$D$76
Name PU_FOUILLE_TRANCHEE: Prix_Unitaires!$D$77
Name PU_GRAVIER: Prix_Unitaires!$D$12
Name PU_HA10: Prix_Unitaires!$D$22
Name PU_HA12: Prix_Unitaires!$D$23
Name PU_HA14: Prix_Unitaires!$D$24

Sheet Notice
A2: DEVIS FACILE BTP
A3: Outil de devis et metre cle en main pour le batiment
A5: A PROPOS DE CE CLASSEUR
B7: Ce classeur calcule automatiquement les quantites de materiaux (metre) puis le cout des
B8: travaux (devis) d'une construction, en appliquant les formules du Guide Pratique du Devis et
B9: Metre (Ir BTP OTEMAKUMI LOTENGO Merlin, edition 2023, www.4geniecivil.com).
B11: Chaque feuille de calcul (Fondation, Elevation, Dalle, Finition, Charpente et Couverture)
B12: reprend la structure et les formules du guide : dosages du beton, quantites unitaires de
B13: sable et gravier, poids des aciers, ratios de bois de coffrage, rendements de peinture et
B14: de carrelage. Les feuilles sont entierement liees entre elles : il suffit de modifier les
B15: dimensions d'un ouvrage pour que toutes les quantites et tous les couts se mettent a jour
B16: automatiquement, jusqu'au devis final.
B18: Maisons a etage : Fondation propose en plus une variante longrine + mur de soubassement,
B19: Elevation repete colonnes / ceinture / linteaux / maconnerie niveau par niveau (RDC, Etage 1,
B20: et ainsi de suite) et ajoute un escalier, Dalle propose une variante plancher hourdis, et
... B22: seul niveau, laissez a 0 les blocs Etage 1 et les variantes non utilisees.
A24: PLAN DU CLASSEUR
B26: Feuille | D26: Contenu
B27: Parametres | C27: Reference | D27: Dosages du beton, quantites unitaires, poids des aciers, ratios bois et clous, rendements peinture et carrelage (donnees issues du guide, ne pas modifier)
B28: Prix_Unitaires | C28: Saisie | D28: Prix des materiaux et taux de main d'oeuvre en FCFA, y compris les prix speciaux immeuble a etage (fouilles, hourdis, mur de soubassement, TVA). C'est ICI que l'on met a jour les prix pour chaque nouveau projet
B29: Fondation | C29: Calcul | D29: Fouilles, remblais, beton de proprete, semelles + amorces de poteaux (socle arme), fondation en moellon OU longrine + mur de soubassement (variante immeuble a etage), chape d'egalisation, beton de sous pavement
B30: Elevation | C30: Calcul | D30: Colonnes, ceinture, linteaux et maconnerie de blocs, repetes niveau par niveau (RDC, Etage 1...), plus un escalier
B31: Dalle | C31: Calcul | D31: Plancher haut de chaque niveau : dalle pleine en beton arme (methode detaillee) OU plancher hourdis (methode composite au m2)
B32: Finition | C32: Calcul | D32: Enduit interieur et exterieur, peinture, carrelage de sol, faience
B33: Charpente_Couverture | C33: Calcul | D33: Fermes et pannes en bois, tolerie de couverture, OU toiture-terrasse accessible avec acrotere (variante immeuble a etage)
B34: Sous_Detail_Prix | C34: Calcul | D34: Prix unitaire tout compris (materiaux + main d'oeuvre) de chaque ouvrage courant, au m3 ou au m2
B35: Devis_Particulier | C35: Resultat | D35: Bordereau detaille par nature de materiaux, corps d'etat par corps d'etat (modele pour un client particulier)
B36: Devis_Entreprise | C36: Resultat | D36: Bordereau par section (terrassement, fondation, RDC, etage, toiture) en prix tout compris, plus second oeuvre forfaitaire et TVA (modele entreprise / bureau d'etudes)
A38: CODE COULEUR
B40: Texte bleu | D40: Cellule de saisie : vous pouvez modifier cette valeur (dimensions, dosage, prix, quantite comptee)
B41: Texte noir | D41: Cellule calculee par une formule : ne pas modifier, la formule se met a jour automatiquement
B42: Texte vert | D42: Cellule qui reprend un resultat d'une autre feuille (lien entre feuilles)
B43: Fond jaune | D43: Hypothese cle a verifier en priorite pour chaque nouveau projet (dosage, prix, ratio)
A45: MODE D'EMPLOI EN 4 ETAPES
B47: 1. Dans Prix_Unitaires, mettre a jour les prix des materiaux et les taux de main d'oeuvre du projet.
B48: 2. Dans chaque feuille de calcul (Fondation, Elevation, Dalle, Finition, Charpente_Couverture),
B49: saisir en bleu les dimensions reelles de l'ouvrage (nombre, longueur, largeur, hauteur, dosage).
B50: 3. Verifier le tableau Resume en bas de chaque feuille : c'est lui qui alimente le devis final.
B51: 4. Consulter Devis_Particulier ou Devis_Entreprise : le montant total se recalcule automatiquement.
A53: Reference : Guide Pratique du Devis et Metre, Ir BTP OTEMAKUMI LOTENGO Merlin (OLM SUPREME), edition 2023, www.4geniecivil.com.
...

Sheet Parametres
A2: PARAMETRES
A3: Constantes et tables de reference issues du Guide Pratique du Devis et Metre
A5: Ces valeurs alimentent, par un nom defini, toutes les formules des autres feuilles. Modifiez-les uniquement si vous appliquez des regles differentes de celles du guide.
A7: 1. BETON FRAIS - COEFFICIENTS PAR M3 (methode volumetrique du guide, §1.4.1)
B9: Grandeur | C9: Valeur | D9: Unite
B10: Poids d'un sac de ciment | C10: 50 | D10: kg
B11: Gravier apparent par m3 de beton (Volume x ce coefficient) | C11: 0.8 | D11: m3 gravier / m3 beton
B12: Densite reelle du gravier | C12: 1.6 | D12: t/m3
B13: Sable apparent par m3 de beton (Volume x ce coefficient) | C13: 0.4 | D13: m3 sable / m3 beton
B14: Densite reelle du sable | C14: 1.5 | D14: t/m3
B15: Volume d'une brouette | C15: 0.06 | D15: m3 (60 litres)
B16: Eau de gachage = Volume x (Dosage / ce facteur) | C16: 2 | D16: kg de ciment par litre d'eau
A17: Formules beton : Ciment(sacs)=Volume x Dosage / Poids_sac | Gravier(t)=Volume x Coef x Densite | Sable(t)=Volume x Coef x Densite | Eau(L)=Volume x Dosage/2
B18: Mortier de hourdage / jointoiement (sans gravier) : sable par m3 de mortier | C18: 1 | D18: m3 sable / m3 mortier (regle pratique)
B19: Mortier de hourdage : eau = ciment(kg) x ce ratio | C19: 0.5 | D19: L d'eau par kg de ciment
A20: Formules mortier de hourdage (moellon) : Ciment(sacs)=Volume x Dosage / Poids_sac | Sable(t)=Volume x Coef_Sable_Mortier x Densite_Sable | Eau(L)=Ciment(kg) x Ratio_Eau_Ciment_Mortier. Pas de gravier dans un mortier.
B21: Mortier de pose (joints) par bloc maconne - ancienne regle forfaitaire, conservee pour reference | C21: 0.003 | D21: m3 de mortier / bloc (non utilisee dans les calculs, remplacee par la methode Sp)
B22: Dosage du mortier de pose des blocs | C22: 300 | D22: kg de ciment/m3
B23: Epaisseur d'un joint de maconnerie | C23: 0.015 | D23: m (1,5 cm), utilise pour la surface Sp du bloc avec joint
A24: Methode du bloc avec joint : Sp = (Longueur_bloc + Joint) x (Hauteur_bloc + Joint). Nombre de blocs = Surface nette / Sp. Volume de mortier = Nombre de blocs x (Sp - Longueur_bloc x Hauteur_bloc) x epaisseur du mur.
A26: 2. DOSAGES COURANTS DU BETON (reference informative - guide p.7-9)
B28: Dosage (kg/m3) | C28: Ciment (sacs 50kg / m3) | D28: Eau (L/m3) | E28: Usage habituel
B29: 150 | C29: =B29/$C$10 -> 3 | D29: =B29/$C$16 -> 75 | E29: Beton de proprete
B30: 200 | C30: =B30/$C$10 -> 4 | D30: =B30/$C$16 -> 100 | E30: Mortier / usage courant
B31: 250 | C31: =B31/$C$10 -> 5 | D31: =B31/$C$16 -> 125 | E31: Fondation en moellon, sous pavement, dallage
B32: 300 | C32: =B32/$C$10 -> 6 | D32: =B32/$C$16 -> 150 | E32: Elevation blocs / mortier renforce
B33: 350 | C33: =B33/$C$10 -> 7 | D33: =B33/$C$16 -> 175 | E33: Beton arme : semelles, colonnes, ceinture, dalle
B34: 400 | C34: =B34/$C$10 -> 8 | D34: =B34/$C$16 -> 200 | E34: Beton arme fortement sollicite
B35: 450 | C35: =B35/$C$10 -> 9 | D35: =B35/$C$16 -> 225 | E35: Beton arme haute resistance
B36: 500 | C36: =B36/$C$10 -> 10 | D36: =B36/$C$16 -> 250 | E36: Beton arme tres haute resistance
A38: 3. ACIERS A HAUTE ADHERENCE - POIDS PAR METRE (guide p.20)
B40: Diametre (mm) | C40: Section (cm2) | D40: Poids (kg/m) | E40: Pieces / tonne
B41: 5 | C41: 0.2 | D41: 0.154 | E41: 540
B42: 6 | C42: 0.283 | D42: 0.222 | E42: 376
B43: 8 | C43: 0.5024 | D43: 0.395 | E43: 211
B44: 10 | C44: 0.78 | D44: 0.617 | E44: 135
B45: 12 | C45: 1.13 | D45: 0.88 | E45: 94
B46: 14 | C46: 1.54 | D46: 1.208 | E46: 69
B47: 16 | C47: 2.01 | D47: 1.578 | E47: 53
B48: 20 | C48: 3.14 | D48: 2.466 | E48: 34
...

Sheet Prix_Unitaires
A2: PRIX UNITAIRES
A3: Prix des materiaux et taux de main d'oeuvre du projet (FCFA) - a mettre a jour pour chaque devis
A5: Toutes les cellules bleues ci-dessous sont modifiables. Elles alimentent automatiquement Sous_Detail_Prix puis les deux devis finaux.
A7: A. MATERIAUX DE BASE
B9: Materiau | C9: Unite | D9: Prix unitaire
B10: Ciment | C10: sac 50kg | D10: 5500
B11: Sable | C11: tonne | D11: 15000
B12: Gravier | C12: tonne | D12: 25000
B13: Moellon | C13: tonne | D13: 17000
B14: Eau de gachage | C14: m3 | D14: 1500
A16: B. ACIERS ET FIL DE LIGATURE (barre commerciale de 12 m)
A18: Aciers HA (haute adherence) : utilises pour l'armature principale. Prix par barre de 12m.
B19: Acier | C19: Unite | D19: Prix unitaire | E19: Diametre (mm)
B20: Rond / HA de 6 mm | C20: barre 12m | D20: 1500 | E20: 6
B21: Rond / HA de 8 mm | C21: barre 12m | D21: 2700 | E21: 8
B22: Rond / HA de 10 mm | C22: barre 12m | D22: 4200 | E22: 10
B23: Rond / HA de 12 mm | C23: barre 12m | D23: 6000 | E23: 12
B24: Rond / HA de 14 mm | C24: barre 12m | D24: 8200 | E24: 14
B25: Rond / HA de 16 mm | C25: barre 12m | D25: 10800 | E25: 16
A27: Aciers ronds lisses (adherence normale) : souvent utilises pour les cadres/etriers, moins chers que le HA. Prix par barre de 12m.
B28: Acier | C28: Unite | D28: Prix unitaire | E28: Diametre (mm)
B29: Rond lisse de 6 mm | C29: barre 12m | D29: 1250 | E29: 6
B30: Rond lisse de 8 mm | C30: barre 12m | D30: 2250 | E30: 8
B31: Rond lisse de 10 mm | C31: barre 12m | D31: 3500 | E31: 10
B32: Rond lisse de 12 mm | C32: barre 12m | D32: 5000 | E32: 12
B33: Fil de ligature (fil de fer recuit) | C33: kg | D33: 1200
A35: C. BOIS, MACONNERIE ET COUVERTURE
B37: Materiau | C37: Unite | D37: Prix unitaire
B38: Planche de coffrage (3,00 x 0,30 x 0,05 m) | C38: piece | D38: 3000
B39: Chevron / madrier (5 x 5 cm, 5 m) | C39: piece | D39: 2200
B40: Clous / pointes | C40: kg | D40: 1000
B41: Bloc creux (agglo) de 15 cm, 40x20 | C41: piece | D41: 350
B42: Bloc creux (agglo) de 20 cm, 40x20 | C42: piece | D42: 450
B43: Tole BG28, 3,00 x 0,90 m | C43: piece | D43: 7500
B44: Tole faitiere, 2,50 m | C44: piece | D44: 8500
B45: Peinture / lasure a bois | C45: litre | D45: 3500
A47: D. FINITION
B49: Materiau | C49: Unite | D49: Prix unitaire
B50: Ciment colle | C50: kg | D50: 650
B51: Chaux | C51: kg | D51: 450
...

Sheet Fondation
A2: 1. FONDATION
A3: Fouilles, beton de proprete, semelles + amorces armees, fondation en moellon, chape, beton de sous pavement, remblais
A5: 1.1 FOUILLES
A7: Fouilles ponctuelles sous chaque semelle isolee.
B8: Designation | C8: Nombre | D8: Longueur (m) | E8: Largeur (m) | F8: Profondeur (m) | G8: Volume unit. (m3) | H8: Volume total (m3)
B9: Fouille semelle - type 1 | C9: 12 | D9: 0.65 | E9: 0.65 | F9: 0.9 | G9: =D9*E9*F9 -> 0.38025 | H9: =G9*C9 -> 4.563
B10: Fouille semelle - type 2 | C10: 0 | D10: 0 | E10: 0 | F10: 0 | G10: =D10*E10*F10 -> 0 | H10: =G10*C10 -> 0
A11: Total fouilles ponctuelles | H11: =SUM(H9:H10) -> 4.563
A13: Fouille en rigole continue (fondation filante). Le perimetre est mesure a l'axe de la tranchee.
B14: Designation | D14: Perimetre (m) | E14: Largeur (m) | F14: Profondeur (m) | H14: Volume total (m3)
B15: Fouille filante (fondation continue) | D15: 60.85 | E15: 0.6 | F15: 0.65 | H15: =D15*E15*F15 -> 23.7315
A16: Note : par simplicite, ce classeur retient UN SEUL perimetre pour toutes les couches de la fondation filante (fouille, beton de proprete, moellon, chape). Si votre semelle filante s'evase avec la profondeur (redans), mesurez et saisissez un perimetre different a chaque section concernee.
A18: 1.2 BETON DE PROPRETE
B20: Dosage (kg/m3) | C20: 150
A21: Sous chaque semelle isolee, puis sous la fondation filante.
B22: Element | C22: Nombre | D22: Longueur / Perimetre (m) | E22: Largeur (m) | F22: Epaisseur (m) | G22: Volume unit. (m3) | H22: Volume total (m3)
B23: Sous semelles isolees | C23: 12 | D23: 0.55 | E23: 0.55 | F23: 0.05 | G23: =D23*E23*F23 -> 0.015125 | H23: =G23*C23 -> 0.1815
B24: Sous fondation filante | D24: =D15 -> 60.85 | E24: 0.4 | F24: 0.05 | H24: =D24*E24*F24 -> 1.217
A25: Volume total beton de proprete | H25: =SUM(H23:H24) -> 1.3985
B26: Materiaux | C26: Formule | G26: Quantite | H26: Unite
B27: Ciment | G27: =ROUNDUP(H25*C20/POIDS_SAC_CIMENT,0) -> 5 | H27: sacs
B28: Gravier | G28: =H25*COEF_GRAVIER_VOL*DENSITE_GRAVIER -> 1.79008 | H28: tonnes
B29: Sable | G29: =H25*COEF_SABLE_VOL*DENSITE_SABLE -> 0.8391 | H29: tonnes
B30: Eau | G30: =H25*C20/EAU_PAR_DOSAGE -> 104.8875 | H30: litres
A32: 1.3 SEMELLE ISOLEE + AMORCE DE POTEAU (SOCLE ARME)
B34: Dosage (kg/m3) | C34: 350
B35: Element | C35: Nombre | D35: Longueur (m) | E35: Largeur (m) | F35: Hauteur (m) | G35: Volume unit. (m3) | H35: Volume total (m3)
B36: Semelle (empattement) | C36: 12 | D36: 0.35 | E36: 0.35 | F36: 0.3 | G36: =D36*E36*F36 -> 0.03675 | H36: =G36*C36 -> 0.441
B37: Colonne / amorce de poteau | C37: 12 | D37: 0.15 | E37: 0.15 | F37: 0.55 | G37: =D37*E37*F37 -> 0.012375 | H37: =G37*C37 -> 0.1485
A38: Volume total beton arme (socle) | H38: =H36+H37 -> 0.5895
B39: Materiaux | G39: Quantite | H39: Unite
B40: Ciment | G40: =ROUNDUP(H38*C34/POIDS_SAC_CIMENT,0) -> 5 | H40: sacs
B41: Gravier | G41: =H38*COEF_GRAVIER_VOL*DENSITE_GRAVIER -> 0.75456 | H41: tonnes
B42: Sable | G42: =H38*COEF_SABLE_VOL*DENSITE_SABLE -> 0.3537 | H42: tonnes
B43: Eau | G43: =H38*C34/EAU_PAR_DOSAGE -> 103.1625 | H43: litres
B45: Armature - maillage de la semelle (2 nappes croisees)
B46: Diametre (mm) | C46: Espacement (m) | D46: Nbre barres/sens | E46: Ld / barre (m) | F46: Recouvrt (m) | G46: Nbre barres 12m | H46: Poids (kg)
B47: 10 | C47: 0.15 | D47: =IF(D36=0,0,ROUNDUP(D36/C47+1,0)) -> 4 | E47: =D36-2*ENROBAGE+2*CROCHET -> 0.51 | F47: =(B47/1000)*INDEX(TAB_NUANCE_COEF,MATCH(NUANCE_HA_DEFAUT,TAB_NUANCE_NOM,0)) -> 0.4 | G47: =IF(E47<=LONG_BARRE_UTILE,ROUNDUP(D47*C36*2/MAX(1,INT(LONG_BARRE_UTILE/E47)),0),D47*C36*2+ROUNDUP(D47*C36*2/MAX(1,INT(LONG_BARRE_UTILE/(E47+F47-LONG_BARRE_UTILE))),0)) -> 5 | H47: =G47*LONG_BARRE_COMMERCIALE*IFERROR(INDEX(TAB_ACIER_POIDS,MATCH(B47,TAB_ACIER_DIAM,0)),0) -> 37.02
A48: Le nombre de files (colonne D) est calcule pour un seul sens ; le nombre total de barres a acheter (colonne G) tient compte des 2 nappes croisees et des 12 semelles.
B50: Armature - colonne / amorce (barres verticales + cadres)
...

Sheet Elevation
A2: 2. ELEVATION
A3: Colonnes, ceinture, linteaux, escalier et maconnerie - niveau par niveau (RDC, Etage 1...)
A5: Pour un batiment a un seul niveau, laissez a 0 les quantites du bloc Etage 1. Pour un batiment R+2 ou plus, dupliquez un bloc Etage (copier les lignes) et ajoutez-le au Resume en bas de feuille.
A7: 2.1 COLONNES / POTEAUX EN BETON ARME
B9: Colonnes - REZ-DE-CHAUSSEE (RDC)
B10: Dosage (kg/m3) | C10: 350
B11: Element | C11: Nombre | D11: Section a (m) | E11: Section b (m) | F11: Hauteur (m) | G11: Volume unit. (m3) | H11: Volume total (m3)
B12: Poteaux | C12: 12 | D12: 0.2 | E12: 0.2 | F12: 3 | G12: =D12*E12*F12 -> 0.12 | H12: =G12*C12 -> 1.44
B13: Ciment | G13: =ROUNDUP(H12*C10/POIDS_SAC_CIMENT,0) -> 11 | H13: sacs
B14: Gravier | G14: =H12*COEF_GRAVIER_VOL*DENSITE_GRAVIER -> 1.8432 | H14: tonnes
B15: Sable | G15: =H12*COEF_SABLE_VOL*DENSITE_SABLE -> 0.864 | H15: tonnes
B16: Eau | G16: =H12*C10/EAU_PAR_DOSAGE -> 252 | H16: litres
B17: Armature principale | C17: 12 | D17: 4 | E17: diam(mm) / nbre barres par poteau
C18: Diametre | D18: Ld/barre (m) | E18: Recouvrt (m) | F18: Nbre files | G18: Nbre barres 12m | H18: Poids (kg)
C19: =C17 -> 12 | D19: =F12-2*ENROBAGE+E19 -> 3.44 | E19: =(C19/1000)*INDEX(TAB_NUANCE_COEF,MATCH(NUANCE_HA_DEFAUT,TAB_NUANCE_NOM,0)) -> 0.48 | F19: =D17*C12 -> 48 | G19: =IF(D19<=LONG_BARRE_UTILE,ROUNDUP(F19/MAX(1,INT(LONG_BARRE_UTILE/D19)),0),F19+ROUNDUP(F19/MAX(1,INT(LONG_BARRE_UTILE/(D19+E19-LONG_BARRE_UTILE))),0)) -> 16 | H19: =G19*LONG_BARRE_COMMERCIALE*IFERROR(INDEX(TAB_ACIER_POIDS,MATCH(C19,TAB_ACIER_DIAM,0)),0) -> 168.96
B20: Cadre | C20: 8 | D20: 0.15 | E20: espacement (m)
C21: Diametre | D21: Nbre cadres | E21: Ld/cadre (m) | F21: Recouvrt (m) | G21: Nbre barres 12m | H21: Poids (kg)
C22: =C20 -> 8 | D22: =IF(F12=0,0,ROUNDUP(F12/D20+1,0)) -> 21 | E22: =((D12-2*ENROBAGE)+(E12-2*ENROBAGE))*2 -> 0.64 | F22: =(C22/1000)*INDEX(TAB_NUANCE_COEF,MATCH(NUANCE_RL_DEFAUT,TAB_NUANCE_NOM,0)) -> 0.4 | G22: =IF(E22<=LONG_BARRE_UTILE,ROUNDUP(D22*C12/MAX(1,INT(LONG_BARRE_UTILE/E22)),0),D22*C12+ROUNDUP(D22*C12/MAX(1,INT(LONG_BARRE_UTILE/(E22+F22-LONG_BARRE_UTILE))),0)) -> 15 | H22: =G22*LONG_BARRE_COMMERCIALE*IFERROR(INDEX(TAB_ACIER_POIDS,MATCH(C22,TAB_ACIER_DIAM,0)),0) -> 71.1
B23: Fil de ligature (5%) | G23: =(H19+H22)*FIL_LIGATURE_PCT -> 12.003 | H23: kg
B24: Coffrage (perimetre x hauteur x nombre) | G24: =(D12*2+E12*2)*F12*C12 -> 28.8 | H24: m2
B25: Nombre de planches | G25: =ROUNDUP((G24/(PLANCHE_L*PLANCHE_LARGEUR))*MAJORATION_ACHAT,0) -> 36
B26: Volume bois (planches) | G26: =G25*PLANCHE_L*PLANCHE_LARGEUR*PLANCHE_e -> 1.62
B27: Traverses (20%) et chevrons | G27: =G26*TRAVERSES_PCT -> 0.324 | H27: =ROUNDUP(G27/CHEVRON_TRAV_V1,0) -> 26 | I27: chevrons
B28: Volume total bois | G28: =G26+G27 -> 1.944 | H28: m3
B29: Clous | G29: =((G26/PLANCHE_e)+(G27/PLANCHE_e))*CLOUS_COFFRAGE_KGM2 -> 5.832 | H29: kg
B31: Colonnes - ETAGE 1
B32: Dosage (kg/m3) | C32: 350
B33: Element | C33: Nombre | D33: Section a (m) | E33: Section b (m) | F33: Hauteur (m) | G33: Volume unit. (m3) | H33: Volume total (m3)
B34: Poteaux | C34: 12 | D34: 0.2 | E34: 0.2 | F34: 2.8 | G34: =D34*E34*F34 -> 0.112 | H34: =G34*C34 -> 1.344
B35: Ciment | G35: =ROUNDUP(H34*C32/POIDS_SAC_CIMENT,0) -> 10 | H35: sacs
B36: Gravier | G36: =H34*COEF_GRAVIER_VOL*DENSITE_GRAVIER -> 1.72032 | H36: tonnes
B37: Sable | G37: =H34*COEF_SABLE_VOL*DENSITE_SABLE -> 0.8064 | H37: tonnes
B38: Eau | G38: =H34*C32/EAU_PAR_DOSAGE -> 235.2 | H38: litres
B39: Armature principale | C39: 12 | D39: 4 | E39: diam(mm) / nbre barres par poteau
C40: Diametre | D40: Ld/barre (m) | E40: Recouvrt (m) | F40: Nbre files | G40: Nbre barres 12m | H40: Poids (kg)
C41: =C39 -> 12 | D41: =F34-2*ENROBAGE+E41 -> 3.24 | E41: =(C41/1000)*INDEX(TAB_NUANCE_COEF,MATCH(NUANCE_HA_DEFAUT,TAB_NUANCE_NOM,0)) -> 0.48 | F41: =D39*C34 -> 48 | G41: =IF(D41<=LONG_BARRE_UTILE,ROUNDUP(F41/MAX(1,INT(LONG_BARRE_UTILE/D41)),0),F41+ROUNDUP(F41/MAX(1,INT(LONG_BARRE_UTILE/(D41+E41-LONG_BARRE_UTILE))),0)) -> 16 | H41: =G41*LONG_BARRE_COMMERCIALE*IFERROR(INDEX(TAB_ACIER_POIDS,MATCH(C41,TAB_ACIER_DIAM,0)),0) -> 168.96
B42: Cadre | C42: 8 | D42: 0.15 | E42: espacement (m)
C43: Diametre | D43: Nbre cadres | E43: Ld/cadre (m) | F43: Recouvrt (m) | G43: Nbre barres 12m | H43: Poids (kg)
C44: =C42 -> 8 | D44: =IF(F34=0,0,ROUNDUP(F34/D42+1,0)) -> 20 | E44: =((D34-2*ENROBAGE)+(E34-2*ENROBAGE))*2 -> 0.64 | F44: =(C44/1000)*INDEX(TAB_NUANCE_COEF,MATCH(NUANCE_RL_DEFAUT,TAB_NUANCE_NOM,0)) -> 0.4 | G44: =IF(E44<=LONG_BARRE_UTILE,ROUNDUP(D44*C34/MAX(1,INT(LONG_BARRE_UTILE/E44)),0),D44*C34+ROUNDUP(D44*C34/MAX(1,INT(LONG_BARRE_UTILE/(E44+F44-LONG_BARRE_UTILE))),0)) -> 15 | H44: =G44*LONG_BARRE_COMMERCIALE*IFERROR(INDEX(TAB_ACIER_POIDS,MATCH(C44,TAB_ACIER_DIAM,0)),0) -> 71.1
B45: Fil de ligature (5%) | G45: =(H41+H44)*FIL_LIGATURE_PCT -> 12.003 | H45: kg
...

Sheet Dalle
A2: 3. PLANCHER (DALLE)
A3: Plancher haut de chaque niveau : dalle pleine (methode detaillee) ou hourdis (methode composite)
A5: Pour chaque niveau, choisissez UNE methode : remplissez soit le bloc 'dalle pleine', soit le bloc 'hourdis', et laissez l'autre a 0 (Nombre/Longueur=0). Le dernier plancher haut (sous toiture ou terrasse) est aussi a saisir ici si vous coulez une dalle plutot qu'une toiture en tole (voir feuille Charpente_Couverture).
A7: 3.1 PLANCHER HAUT RDC (entre RDC et Etage 1)
B9: Dalle pleine - Plancher haut RDC
B10: Dosage (kg/m3) | C10: 350
B11: Element | C11: Longueur L (m) | D11: Largeur l (m) | E11: Epaisseur e (m) | H11: Volume total (m3)
B12: Dalle pleine | C12: 9.65 | D12: 7.15 | E12: 0.1 | H12: =C12*D12*E12 -> 6.89975
B13: Ciment | G13: =ROUNDUP(H12*C10/POIDS_SAC_CIMENT,0) -> 49 | H13: sacs
B14: Gravier | G14: =H12*COEF_GRAVIER_VOL*DENSITE_GRAVIER -> 8.83168 | H14: tonnes
B15: Sable | G15: =H12*COEF_SABLE_VOL*DENSITE_SABLE -> 4.13985 | H15: tonnes
B16: Eau | G16: =H12*C10/EAU_PAR_DOSAGE -> 1207.4563 | H16: litres
C17: Diametre | D17: Espacement (m) | E17: Nbre files | F17: Ld (m) | G17: Nbre barres 12m | H17: Poids (kg)
C18: 10 | D18: 0.15 | E18: =IF(D12=0,0,ROUNDUP(D12/D18+1,0)) -> 49 | F18: =C12-2*ENROBAGE -> 9.61 | G18: =IF(F18<=LONG_BARRE_UTILE,ROUNDUP(E18/MAX(1,INT(LONG_BARRE_UTILE/F18)),0),E18+ROUNDUP(E18/MAX(1,INT(LONG_BARRE_UTILE/(F18+ROUND((C18/1000)*INDEX(TAB_NUANCE_COEF,MATCH(NUANCE_HA_DEFAUT,TAB_NUANCE_NOM,0)),3)-LONG_BARRE_UTILE))),0)) -> 49 | H18: =G18*LONG_BARRE_COMMERCIALE*IFERROR(INDEX(TAB_ACIER_POIDS,MATCH(C18,TAB_ACIER_DIAM,0)),0) -> 362.796
C19: Diametre | D19: Espacement (m) | E19: Nbre files | F19: Ld (m) | G19: Nbre barres 12m | H19: Poids (kg)
C20: 10 | D20: 0.15 | E20: =IF(C12=0,0,ROUNDUP(C12/D20+1,0)) -> 66 | F20: =D12-2*ENROBAGE -> 7.11 | G20: =IF(F20<=LONG_BARRE_UTILE,ROUNDUP(E20/MAX(1,INT(LONG_BARRE_UTILE/F20)),0),E20+ROUNDUP(E20/MAX(1,INT(LONG_BARRE_UTILE/(F20+ROUND((C20/1000)*INDEX(TAB_NUANCE_COEF,MATCH(NUANCE_HA_DEFAUT,TAB_NUANCE_NOM,0)),3)-LONG_BARRE_UTILE))),0)) -> 66 | H20: =G20*LONG_BARRE_COMMERCIALE*IFERROR(INDEX(TAB_ACIER_POIDS,MATCH(C20,TAB_ACIER_DIAM,0)),0) -> 488.664
B21: Fil de ligature (5%) | G21: =(H18+H20)*FIL_LIGATURE_PCT -> 42.573 | H21: kg
B22: Coffrage / etaiement (surface x ratio) | G22: =C12*D12*RATIO_COFFRAGE_DALLE -> 77.2772 | H22: m2
B23: Nombre de planches | G23: =ROUNDUP((G22/(PLANCHE_L*PLANCHE_LARGEUR))*MAJORATION_ACHAT,0) -> 95
B24: Volume bois (planches) | G24: =G23*PLANCHE_L*PLANCHE_LARGEUR*PLANCHE_e -> 4.275
B25: Traverses (20%) et chevrons | G25: =G24*TRAVERSES_PCT -> 0.855 | H25: =ROUNDUP(G25/CHEVRON_TRAV_V1,0) -> 69 | I25: chevrons
B26: Volume total bois | G26: =G24+G25 -> 5.13 | H26: m3
B27: Clous | G27: =((G24/PLANCHE_e)+(G25/PLANCHE_e))*CLOUS_COFFRAGE_KGM2 -> 15.39 | H27: kg
B29: Hourdis - Plancher haut RDC
B30: Element | C30: Longueur (m) | D30: Largeur (m) | E30: Type | G30: Surface | H30: Unite
B31: Plancher hourdis | C31: 0 | D31: 0 | E31: 12+4 | G31: =C31*D31 -> 0 | H31: m2
A32: Type '12+4' ou '16+4' (hourdis + dalle de compression) : systeme livre et pose par un fournisseur specialise, prix tout compris au m2 (voir Sous_Detail_Prix).
A34: 3.2 PLANCHER HAUT ETAGE 1 (toiture-terrasse ou sous comble)
B36: Dalle pleine - Plancher haut Etage 1
B37: Dosage (kg/m3) | C37: 350
B38: Element | C38: Longueur L (m) | D38: Largeur l (m) | E38: Epaisseur e (m) | H38: Volume total (m3)
B39: Dalle pleine | C39: 0 | D39: 0 | E39: 0.1 | H39: =C39*D39*E39 -> 0
B40: Ciment | G40: =ROUNDUP(H39*C37/POIDS_SAC_CIMENT,0) -> 0 | H40: sacs
B41: Gravier | G41: =H39*COEF_GRAVIER_VOL*DENSITE_GRAVIER -> 0 | H41: tonnes
B42: Sable | G42: =H39*COEF_SABLE_VOL*DENSITE_SABLE -> 0 | H42: tonnes
B43: Eau | G43: =H39*C37/EAU_PAR_DOSAGE -> 0 | H43: litres
C44: Diametre | D44: Espacement (m) | E44: Nbre files | F44: Ld (m) | G44: Nbre barres 12m | H44: Poids (kg)
C45: 10 | D45: 0.15 | E45: =IF(D39=0,0,ROUNDUP(D39/D45+1,0)) -> 0 | F45: =C39-2*ENROBAGE -> -0.04 | G45: =IF(F45<=LONG_BARRE_UTILE,ROUNDUP(E45/MAX(1,INT(LONG_BARRE_UTILE/F45)),0),E45+ROUNDUP(E45/MAX(1,INT(LONG_BARRE_UTILE/(F45+ROUND((C45/1000)*INDEX(TAB_NUANCE_COEF,MATCH(NUANCE_HA_DEFAUT,TAB_NUANCE_NOM,0)),3)-LONG_BARRE_UTILE))),0)) -> 0 | H45: =G45*LONG_BARRE_COMMERCIALE*IFERROR(INDEX(TAB_ACIER_POIDS,MATCH(C45,TAB_ACIER_DIAM,0)),0) -> 0
C46: Diametre | D46: Espacement (m) | E46: Nbre files | F46: Ld (m) | G46: Nbre barres 12m | H46: Poids (kg)
C47: 10 | D47: 0.15 | E47: =IF(C39=0,0,ROUNDUP(C39/D47+1,0)) -> 0 | F47: =D39-2*ENROBAGE -> -0.04 | G47: =IF(F47<=LONG_BARRE_UTILE,ROUNDUP(E47/MAX(1,INT(LONG_BARRE_UTILE/F47)),0),E47+ROUNDUP(E47/MAX(1,INT(LONG_BARRE_UTILE/(F47+ROUND((C47/1000)*INDEX(TAB_NUANCE_COEF,MATCH(NUANCE_HA_DEFAUT,TAB_NUANCE_NOM,0)),3)-LONG_BARRE_UTILE))),0)) -> 0 | H47: =G47*LONG_BARRE_COMMERCIALE*IFERROR(INDEX(TAB_ACIER_POIDS,MATCH(C47,TAB_ACIER_DIAM,0)),0) -> 0
...

Sheet Finition
A2: 4. FINITION
A3: Enduit, peinture, carrelage de sol et faience
A5: 4.1 ENDUIT (INTERIEUR + EXTERIEUR)
B7: Element | C7: Surface (m2) | G7: Quantite | H7: Unite
B8: Surface totale a enduire (2 faces des murs) | C8: 159
B9: Ciment | G9: =ROUNDUP(C8*ENDUIT_CIMENT_KGM2/POIDS_SAC_CIMENT,0) -> 26 | H9: sacs
B10: Sable | G10: =(G9*POIDS_SAC_CIMENT/DOSAGE_MORTIER_MACONNERIE)*COEF_SABLE_MORTIER*DENSITE_SABLE -> 6.5 | H10: tonnes
B11: Eau | G11: =(G9*POIDS_SAC_CIMENT)*RATIO_EAU_CIMENT_MORTIER -> 650 | H11: litres
A13: Regle du guide (p.12) : 8 kg de ciment par m2 a enduire. Le sable et l'eau suivent le meme mortier de pose que la maconnerie (dosage 300 kg/m3).
A15: 4.2 PEINTURE
B17: Element | C17: Surface (m2) | G17: Quantite | H17: Unite
B18: Surface totale a peindre | C18: 159
A19: Les 3 lignes ci-dessous sont 3 options alternatives (meme surface) : le devis final n'en retient qu'une (peinture latex par defaut).
B20: Option A - Peinture latex (2 couches) | G20: =C18/PEINTURE_LATEX_M2_KG -> 39.75 | H20: kg
B21: Option B - Peinture classique (glycero/eau) | G21: =(C18/PEINTURE_CLASSIQUE_M2_L)*NB_COUCHES_PEINTURE -> 31.8 | H21: litres
B22: Option C - Badigeon a la chaux | G22: =(C18/CHAUX_M2_KG)*NB_COUCHES_PEINTURE -> 53 | H22: kg
A24: 4.3 CARRELAGE DE SOL
B26: Element | C26: Surface (m2) | D26: Epaisseur mortier (m) | G26: Quantite | H26: Unite
B27: Surface de sol a carreler | C27: 69.05 | D27: 0.03
B28: Nombre de carreaux (30x30, majore de 10%) | G28: =ROUNDUP((C27/CARREAUX_S1)*MAJORATION_CARRELAGE,0) -> 844 | H28: pieces
B29: Cartons de carreaux (12 pieces) | G29: =ROUNDUP(G28/12,0) -> 71 | H29: cartons
B30: Ciment colle | G30: =C27*CIMENT_COLLE_KGM2 -> 552.4 | H30: kg
B31: Sable du mortier de pose | G31: =C27*(D27*100)*SABLE_MORTIER_L_CM_M2*DENSITE_SABLE/1000 -> 3.10725 | H31: tonnes
B32: Ciment du mortier de pose | G32: =ROUNDUP((C27*D27)*DOSAGE_MORTIER_MACONNERIE/POIDS_SAC_CIMENT,0) -> 13 | H32: sacs
A34: 4.4 FAIENCE MURALE (cuisine, sanitaires)
B36: Element | C36: Surface (m2) | G36: Quantite | H36: Unite
B37: Surface murale a habiller | C37: 25
B38: Nombre de faience (25x40, majore de 10%) | G38: =ROUNDUP((C37/FAIENCE_S1)*MAJORATION_CARRELAGE,0) -> 275 | H38: pieces
B39: Cartons de faience (10 pieces) | G39: =ROUNDUP(G38/10,0) -> 28 | H39: cartons
B40: Ciment colle | G40: =C37*CIMENT_COLLE_KGM2 -> 200 | H40: kg
A42: 4.5 RESUME FINITION
B44: Materiau | G44: Quantite totale | H44: Unite
B45: Ciment (enduit + mortier de pose carrelage) | G45: =G9+G32 -> 39 | H45: sacs
B46: Sable (enduit + mortier de pose carrelage) | G46: =G10+G31 -> 9.60725 | H46: tonnes
B47: Eau | G47: =G11 -> 650 | H47: litres
B48: Ciment colle (carrelage + faience) | G48: =G30+G40 -> 752.4 | H48: kg
B49: Peinture latex (option retenue par defaut) | G49: =G20 -> 39.75 | H49: kg
B50: Carreaux de sol | G50: =G29 -> 71 | H50: cartons
B51: Faience murale | G51: =G39 -> 28 | H51: cartons
A53: Surfaces retenues pour le devis (pour reference).
...

Sheet Charpente_Couverture
A2: 5. CHARPENTE ET COUVERTURE
A3: Fermes et pannes en bois (methode simplifiee), tolerie de couverture
A5: 5.1 CHARPENTE BOIS
A7: Methode simplifiee : la longueur developpee de chaque ferme (entrait + 2 arbaletriers) est majoree forfaitairement de 15% pour couvrir poinçon, fiches, contre-fiches et assemblages. Pour une charpente complexe, faites calculer la note de charpente par un bureau d'etudes.
B8: Parametre | C8: Valeur | D8: Unite
B9: Largeur du batiment (portee) | C9: 7.15 | D9: m
B10: Longueur du batiment | C10: 9.65 | D10: m
B11: Debord de toiture (chaque cote) | C11: 0.5 | D11: m
B12: Hauteur au faitage (par rapport a l'entrait) | C12: 1.5 | D12: m
B13: Ecartement entre fermes | C13: 2.5 | D13: m
B14: Section du bois (entrait / arbaletrier / panne) | C14: 0.08 | D14: 0.08 | E14: m x m
B16: Calcul | G16: Valeur | H16: Unite
B17: Nombre de fermes | G17: =ROUNDUP(C10/C13+1,0) -> 5
B18: Entrait (portee + 2 debords) | G18: =C9+2*C11 -> 8.15 | H18: m
B19: Arbaletrier (par pente) | G19: =SQRT((G18/2)^2+C12^2) -> 4.3423064 | H19: m
B20: Longueur developpee par ferme (entrait + 2 arbaletriers, +15%) | G20: =(G18+2*G19)*1.15 -> 19.359805 | H20: m
B21: Volume de bois des fermes | G21: =G17*G20*C14*D14 -> 0.61951375 | H21: m3
B23: Pannes | C23: Nombre de lignes / versant | D23: Longueur (m) | G23: Volume | H23: Unite
B24: Pannes (2 versants) | C24: 5 | D24: =C10+2*C11 -> 10.65 | G24: =C24*2*D24*C14*D14 -> 0.6816 | H24: m3
A25: Volume total de bois de charpente | G25: =G21+G24 -> 1.3011138
B26: Clous / boulons de charpente | G26: =G25*CLOUS_CHARPENTE_KGM3 -> 26.022275 | H26: kg
A28: 5.2 COUVERTURE EN TOLES
B30: Element | C30: Valeur | D30: Unite
B31: Surface a couvrir = (long. + 2 debords) x (larg. + 2 debords) | C31: =(C10+2*C11)*(C9+2*C11) -> 86.7975 | D31: m2
B32: Largeur utile d'une tole (apres recouvrement) | C32: 0.85 | D32: m
B33: Longueur d'une tole | C33: 3 | D33: m
B35: Calcul | G35: Valeur | H35: Unite
B36: Nombre de toles (2 pans, majore de 10%) | G36: =ROUNDUP((C31/(C32*C33))*MAJORATION_ACHAT,0)*2 -> 76 | H36: pieces
B37: Longueur d'une tole faitiere | C37: 2.5 | D37: m
B38: Nombre de toles faitieres | G38: =ROUNDUP(C10/C37,0)+1 -> 5 | H38: pieces
B39: Clous / pointes de couverture | G39: =(C31*2)*CLOUS_COUVERTURE_KGM2 -> 17.3595 | H39: kg
A41: 5.3 TOITURE-TERRASSE ACCESSIBLE (variante plate, immeuble a etage)
A43: Variante de toiture plate avec acrotere, utilisee a la place de la charpente+couverture en tole (bloc 5.1-5.2) pour un immeuble a etage. Laissez a 0 la surface non utilisee (charpente/couverture OU terrasse).
B44: Dosage (kg/m3) | C44: 350
B45: Acrotere | C45: Perimetre (m) | D45: Largeur b (m) | E45: Hauteur H (m) | H45: Volume (m3)
B46: Chainage de couronnement sur acrotere | C46: 33.6 | D46: 0.15 | E46: 0.15 | H46: =C46*D46*E46 -> 0.756
B47: Ciment | G47: =ROUNDUP(H46*C44/POIDS_SAC_CIMENT,0) -> 6 | H47: sacs
B48: Gravier | G48: =H46*COEF_GRAVIER_VOL*DENSITE_GRAVIER -> 0.96768 | H48: tonnes
B49: Sable | G49: =H46*COEF_SABLE_VOL*DENSITE_SABLE -> 0.4536 | H49: tonnes
B50: Eau | G50: =H46*C44/EAU_PAR_DOSAGE -> 132.3 | H50: litres
...

Sheet Sous_Detail_Prix
A2: SOUS DETAIL DES PRIX UNITAIRES
A3: Prix tout compris (materiaux + main d'oeuvre) de chaque ouvrage courant. Alimente Devis_Entreprise.
A5: Principe du guide : "1 m3 de beton arme dose a 350 kg/m3 vaut X FCFA, ceci comprend les materiaux, la main d'oeuvre et les divers". Les ratios en bleu ci-dessous sont des moyennes generales a ajuster selon votre projet.
B7: Prix moyen de l'acier pose (base HA10) | C7: =PU_HA10/(LONG_BARRE_COMMERCIALE*IFERROR(INDEX(TAB_ACIER_POIDS,MATCH(10,TAB_ACIER_DIAM,0)),1)) -> 567.26094 | D7: FCFA/kg
B8: Prix moyen du bois de coffrage | C8: =PU_PLANCHE/(PLANCHE_L*PLANCHE_LARGEUR*PLANCHE_e) -> 66666.667 | D8: FCFA/m3
A10: BETON DE PROPRETE (non arme)
B12: Composante | C12: Quantite / m3 | D12: Prix unitaire | E12: Cout / m3
B13: Dosage | C13: 150 | D13: kg/m3
B14: Ciment | C14: =C13/POIDS_SAC_CIMENT -> 3 | D14: =PU_CIMENT -> 5500 | E14: =C14*D14 -> 16500
B15: Gravier | C15: =COEF_GRAVIER_VOL*DENSITE_GRAVIER -> 1.28 | D15: =PU_GRAVIER -> 25000 | E15: =C15*D15 -> 32000
B16: Sable | C16: =COEF_SABLE_VOL*DENSITE_SABLE -> 0.6 | D16: =PU_SABLE -> 15000 | E16: =C16*D16 -> 9000
B17: Eau | C17: =(C13/EAU_PAR_DOSAGE)/1000 -> 0.075 | D17: =PU_EAU -> 1500 | E17: =C17*D17 -> 112.5
A18: Prix materiaux / m3 | E18: =(E14+E15+E16+E17) -> 57612.5
B19: Main d'oeuvre | C19: =PU_MO_POURCENT -> 0.28 | E19: =E18*C19 -> 16131.5
A20: PRIX TOUT COMPRIS / m3 | E20: =E18+E19 -> 73744
A22: BETON DOSE A 250 kg/m3 (non arme : chape, sous pavement)
B24: Composante | C24: Quantite / m3 | D24: Prix unitaire | E24: Cout / m3
B25: Dosage | C25: 250 | D25: kg/m3
B26: Ciment | C26: =C25/POIDS_SAC_CIMENT -> 5 | D26: =PU_CIMENT -> 5500 | E26: =C26*D26 -> 27500
B27: Gravier | C27: =COEF_GRAVIER_VOL*DENSITE_GRAVIER -> 1.28 | D27: =PU_GRAVIER -> 25000 | E27: =C27*D27 -> 32000
B28: Sable | C28: =COEF_SABLE_VOL*DENSITE_SABLE -> 0.6 | D28: =PU_SABLE -> 15000 | E28: =C28*D28 -> 9000
B29: Eau | C29: =(C25/EAU_PAR_DOSAGE)/1000 -> 0.125 | D29: =PU_EAU -> 1500 | E29: =C29*D29 -> 187.5
A30: Prix materiaux / m3 | E30: =(E26+E27+E28+E29) -> 68687.5
B31: Main d'oeuvre | C31: =PU_MO_POURCENT -> 0.28 | E31: =E30*C31 -> 19232.5
A32: PRIX TOUT COMPRIS / m3 | E32: =E30+E31 -> 87920
A34: BETON ARME DOSE A 350 kg/m3 (semelles, colonnes, ceinture, dalle)
B36: Composante | C36: Quantite / m3 | D36: Prix unitaire | E36: Cout / m3
B37: Dosage | C37: 350 | D37: kg/m3
B38: Ciment | C38: =C37/POIDS_SAC_CIMENT -> 7 | D38: =PU_CIMENT -> 5500 | E38: =C38*D38 -> 38500
B39: Gravier | C39: =COEF_GRAVIER_VOL*DENSITE_GRAVIER -> 1.28 | D39: =PU_GRAVIER -> 25000 | E39: =C39*D39 -> 32000
B40: Sable | C40: =COEF_SABLE_VOL*DENSITE_SABLE -> 0.6 | D40: =PU_SABLE -> 15000 | E40: =C40*D40 -> 9000
B41: Eau | C41: =(C37/EAU_PAR_DOSAGE)/1000 -> 0.175 | D41: =PU_EAU -> 1500 | E41: =C41*D41 -> 262.5
B42: Acier (ratio moyen, a ajuster) | C42: 130 | D42: =C7 -> 567.26094 | E42: =C42*D42 -> 73743.922
B43: Coffrage bois (ratio moyen, a ajuster) | C43: 0.9 | D43: =C8 -> 66666.667 | E43: =C43*D43 -> 60000
A44: Prix materiaux / m3 | E44: =(E38+E39+E40+E41+E42+E43) -> 213506.42
B45: Main d'oeuvre | C45: =PU_MO_POURCENT -> 0.28 | E45: =E44*C45 -> 59781.798
A46: PRIX TOUT COMPRIS / m3 | E46: =E44+E45 -> 273288.22
A48: MACONNERIE EN MOELLON (par m3)
B50: Composante | C50: Quantite / m3 | D50: Prix unitaire | E50: Cout / m3
B51: Dosage du mortier de hourdage | C51: 250 | D51: kg/m3
...

Sheet Devis_Particulier
A2: BORDEREAU QUANTITATIF ET ESTIMATIF DES TRAVAUX D'UN BATIMENT
A3: Devis detaille par nature de materiaux, corps d'etat par corps d'etat (modele particulier)
A5: Structure reprise du modele fourni (bordereau par corps d'etat). Chaque quantite est liee aux feuilles de calcul ; chaque prix unitaire est liee a Prix_Unitaires / Sous_Detail_Prix.
B7: Designation | C7: Unite | D7: Qtte | E7: P.U (FCFA) | F7: P.T (FCFA)
B8: TERRASSEMENT ET INSTALLATION DE CHANTIER
A9: 1 | B9: Installation de chantier | C9: fft | D9: =1 -> 1 | E9: =PU_AMENEE_REPLI -> 200000 | F9: =D9*E9 -> 200000
A10: 2 | B10: Fouilles en puits (semelles isolees) | C10: m3 | D10: =Fondation!$G$162 -> 4.563 | E10: =PU_FOUILLE_PUITS -> 1886 | F10: =D10*E10 -> 8605.818
A11: 3 | B11: Fouilles en tranchee (longrines/fondation filante) | C11: m3 | D11: =Fondation!$G$163 -> 23.7315 | E11: =PU_FOUILLE_TRANCHEE -> 1162 | F11: =D11*E11 -> 27576.003
A12: 4 | B12: Remblais | C12: m3 | D12: =Fondation!$G$160 -> 46.868575 | E12: =PU_REMBLAI_FONDATION -> 1505 | F12: =D12*E12 -> 70537.205
A13: 5 | B13: Evacuation des deblais excedentaires | C13: m3 | D13: =Fondation!$G$161 -> 0 | E13: =PU_EVACUATION_DEBLAIS -> 1500 | F13: =D13*E13 -> 0
A14: Sous total Terrassement | F14: =SUM(F9:F13) -> 306719.03
B16: FONDATION
A17: 6 | B17: Ciment | C17: sac | D17: =Fondation!$G$169 -> 94 | E17: =PU_CIMENT -> 5500 | F17: =D17*E17 -> 517000
A18: 7 | B18: Gravier | C18: tonne | D18: =Fondation!$G$170 -> 17.50368 | E18: =PU_GRAVIER -> 25000 | F18: =D18*E18 -> 437592
A19: 8 | B19: Sable | C19: tonne | D19: =Fondation!$G$171 -> 13.1337 | E19: =PU_SABLE -> 15000 | F19: =D19*E19 -> 197005.5
A20: 9 | B20: Eau | C20: m3 | D20: =(Fondation!$G$172)/1000 -> 2.2723937 | E20: =PU_EAU -> 1500 | F20: =D20*E20 -> 3408.5906
A21: 10 | B21: Moellon | C21: tonne | D21: =Fondation!$G$173 -> 12.26736 | E21: =PU_MOELLON -> 17000 | F21: =D21*E21 -> 208545.12
A22: 11 | B22: Mur de soubassement en agglos pleins | C22: m2 | D22: =Fondation!$G$165 -> 36.51 | E22: =PU_MUR_SOUBASSEMENT -> 6045 | F22: =D22*E22 -> 220702.95
A23: 12 | B23: Bois de coffrage (planches) | C23: piece | D23: =Fondation!$G$174 -> 64 | E23: =PU_PLANCHE -> 3000 | F23: =D23*E23 -> 192000
A24: 13 | B24: Bois de coffrage (chevrons) | C24: piece | D24: =Fondation!$G$175 -> 47 | E24: =PU_CHEVRON -> 2200 | F24: =D24*E24 -> 103400
A25: 14 | B25: Clous | C25: kg | D25: =Fondation!$G$177 -> 10.368 | E25: =PU_CLOUS -> 1000 | F25: =D25*E25 -> 10368
A26: 15 | B26: Armature - maillage de semelle | C26: barre 12m | D26: =Fondation!$G$182 -> 5 | E26: =IFERROR(INDEX(TAB_PRIX_ACIER_VAL,MATCH(Fondation!$C$182,TAB_PRIX_ACIER_DIAM,0)),0) -> 4200 | F26: =D26*E26 -> 21000
A27: 16 | B27: Armature - colonne/amorce | C27: barre 12m | D27: =Fondation!$G$183 -> 6 | E27: =IFERROR(INDEX(TAB_PRIX_ACIER_VAL,MATCH(Fondation!$C$183,TAB_PRIX_ACIER_DIAM,0)),0) -> 4200 | F27: =D27*E27 -> 25200
A28: 17 | B28: Armature - cadre socle | C28: barre 12m | D28: =Fondation!$G$184 -> 3 | E28: =IFERROR(INDEX(TAB_PRIX_ACIER_RL_VAL,MATCH(Fondation!$C$184,TAB_PRIX_ACIER_RL_DIAM,0)),0) -> 2250 | F28: =D28*E28 -> 6750
A29: 18 | B29: Armature - longrine principale | C29: barre 12m | D29: =Fondation!$G$185 -> 8 | E29: =IFERROR(INDEX(TAB_PRIX_ACIER_VAL,MATCH(Fondation!$C$185,TAB_PRIX_ACIER_DIAM,0)),0) -> 6000 | F29: =D29*E29 -> 48000
A30: 19 | B30: Armature - longrine cadre | C30: barre 12m | D30: =Fondation!$G$186 -> 24 | E30: =IFERROR(INDEX(TAB_PRIX_ACIER_RL_VAL,MATCH(Fondation!$C$186,TAB_PRIX_ACIER_RL_DIAM,0)),0) -> 1250 | F30: =D30*E30 -> 30000
A31: 20 | B31: Fil a ligaturer | C31: kg | D31: =Fondation!$G$178 -> 12.204 | E31: =PU_FIL -> 1200 | F31: =D31*E31 -> 14644.8
A32: Sous total Fondation | F32: =SUM(F17:F31) -> 2035617
B34: ELEVATION (RDC + ETAGE)
A35: 21 | B35: Blocs / agglos creux | C35: piece | D35: =Elevation!$G$209 -> 1774 | E35: =PU_BLOC15 -> 350 | F35: =D35*E35 -> 620900
A36: 22 | B36: Ciment | C36: sac | D36: =Elevation!$G$205 -> 81 | E36: =PU_CIMENT -> 5500 | F36: =D36*E36 -> 445500
A37: 23 | B37: Gravier | C37: tonne | D37: =Elevation!$G$206 -> 11.34976 | E37: =PU_GRAVIER -> 25000 | F37: =D37*E37 -> 283744
A38: 24 | B38: Sable | C38: tonne | D38: =Elevation!$G$207 -> 8.667617 | E38: =PU_SABLE -> 15000 | F38: =D38*E38 -> 130014.26
A39: 25 | B39: Eau | C39: m3 | D39: =(Elevation!$G$208)/1000 -> 1.926725 | E39: =PU_EAU -> 1500 | F39: =D39*E39 -> 2890.0875
A40: 26 | B40: Bois de coffrage (planches) | C40: piece | D40: =Elevation!$G$210 -> 169 | E40: =PU_PLANCHE -> 3000 | F40: =D40*E40 -> 507000
A41: 27 | B41: Bois de coffrage (chevrons) | C41: piece | D41: =Elevation!$G$211 -> 76 | E41: =PU_CHEVRON -> 2200 | F41: =D41*E41 -> 167200
A42: 28 | B42: Clous | C42: kg | D42: =Elevation!$G$213 -> 27.378 | E42: =PU_CLOUS -> 1000 | F42: =D42*E42 -> 27378
A43: 29 | B43: Armature - Colonnes RDC - principale | C43: barre 12m | D43: =Elevation!$G$218 -> 16 | E43: =IFERROR(INDEX(TAB_PRIX_ACIER_VAL,MATCH(Elevation!$C$218,TAB_PRIX_ACIER_DIAM,0)),0) -> 6000 | F43: =D43*E43 -> 96000
A44: 30 | B44: Armature - Colonnes RDC - cadre | C44: barre 12m | D44: =Elevation!$G$219 -> 15 | E44: =IFERROR(INDEX(TAB_PRIX_ACIER_RL_VAL,MATCH(Elevation!$C$219,TAB_PRIX_ACIER_RL_DIAM,0)),0) -> 2250 | F44: =D44*E44 -> 33750
A45: 31 | B45: Armature - Colonnes Etage1 - principale | C45: barre 12m | D45: =Elevation!$G$220 -> 16 | E45: =IFERROR(INDEX(TAB_PRIX_ACIER_VAL,MATCH(Elevation!$C$220,TAB_PRIX_ACIER_DIAM,0)),0) -> 6000 | F45: =D45*E45 -> 96000
...

Sheet Devis_Entreprise
A2: DEVIS QUANTITATIF & ESTIMATIF - VILLA R+1
A3: Gros oeuvre par section (prix tout compris) + second oeuvre forfaitaire + TVA - modele entreprise
A5: Structure reprise du modele fourni. Le gros oeuvre est chiffre section par section avec les prix tout compris de Prix_Unitaires / Sous_Detail_Prix, relies aux feuilles de calcul. Le second oeuvre (menuiserie, plomberie, electricite...) n'est pas modelise dans ce classeur : saisissez vos propres forfaits en bleu.
B7: Designation | C7: Unite | D7: Quantite | E7: Prix unitaire | F7: Prix total
B8: TERRASSEMENTS ET PREPARATION DU CHANTIER
A9: 1 | B9: Amenee et repli de materiel | C9: ens | D9: =1 -> 1 | E9: =PU_AMENEE_REPLI -> 200000 | F9: =D9*E9 -> 200000
A10: 2 | B10: Fouilles en puits pour semelles isolees | C10: m3 | D10: =Fondation!$G$162 -> 4.563 | E10: =PU_FOUILLE_PUITS -> 1886 | F10: =D10*E10 -> 8605.818
A11: 3 | B11: Fouilles en tranchee pour longrines | C11: m3 | D11: =Fondation!$G$163 -> 23.7315 | E11: =PU_FOUILLE_TRANCHEE -> 1162 | F11: =D11*E11 -> 27576.003
A12: 4 | B12: Remblais (fondations + sous dallage) | C12: m3 | D12: =Fondation!$G$160 -> 46.868575 | E12: =PU_REMBLAI_FONDATION -> 1505 | F12: =D12*E12 -> 70537.205
A13: 5 | B13: Evacuation des deblais excedentaires | C13: m3 | D13: =Fondation!$G$161 -> 0 | E13: =PU_EVACUATION_DEBLAIS -> 1500 | F13: =D13*E13 -> 0
A14: Sous-total Terrassements et preparation | F14: =SUM(F9:F13) -> 306719.03
B16: I - FONDATION
A17: 1 | B17: Beton de proprete (dose a 150 kg/m3) | C17: m3 | D17: =Fondation!$G$154 -> 1.3985 | E17: =Sous_Detail_Prix!$E$20 -> 73744 | F17: =D17*E17 -> 103130.98
A18: 2 | B18: Beton arme dose a 350 kg/m3 (semelles + amorces) | C18: m3 | D18: =Fondation!$G$155 -> 0.5895 | E18: =Sous_Detail_Prix!$E$46 -> 273288.22 | F18: =D18*E18 -> 161103.41
A19: 3 | B19: Beton arme dose a 350 kg/m3 (longrine) | C19: m3 | D19: =Fondation!$G$164 -> 3.57 | E19: =Sous_Detail_Prix!$E$46 -> 273288.22 | F19: =D19*E19 -> 975638.95
A20: 4 | B20: Fondation en moellon | C20: m3 | D20: =Fondation!$G$156 -> 10.953 | E20: =Sous_Detail_Prix!$E$57 -> 43571.2 | F20: =D20*E20 -> 477235.35
A21: 5 | B21: Chape d'egalisation (dosee a 250 kg/m3) | C21: m3 | D21: =Fondation!$G$157 -> 1.217 | E21: =Sous_Detail_Prix!$E$32 -> 87920 | F21: =D21*E21 -> 106998.64
A22: 6 | B22: Beton de sous pavement (dose a 250 kg/m3) | C22: m3 | D22: =Fondation!$G$158 -> 6.89975 | E22: =Sous_Detail_Prix!$E$32 -> 87920 | F22: =D22*E22 -> 606626.02
A23: 7 | B23: Mur de soubassement en agglos pleins de 15 | C23: m2 | D23: =Fondation!$G$165 -> 36.51 | E23: =PU_MUR_SOUBASSEMENT -> 6045 | F23: =D23*E23 -> 220702.95
A24: Sous-total Fondation | F24: =SUM(F17:F23) -> 2651436.3
B26: II - RDC
A27: 1 | B27: Beton arme dose a 350 kg/m3 (poteaux) | C27: m3 | D27: =Elevation!$G$193 -> 1.44 | E27: =Sous_Detail_Prix!$E$46 -> 273288.22 | F27: =D27*E27 -> 393535.04
A28: 2 | B28: Beton arme dose a 350 kg/m3 (ceinture) | C28: m3 | D28: =Elevation!$G$195 -> 1.008 | E28: =Sous_Detail_Prix!$E$46 -> 273288.22 | F28: =D28*E28 -> 275474.53
A29: 3 | B29: Beton arme dose a 350 kg/m3 (linteaux et appuis) | C29: m3 | D29: =Elevation!$G$197 -> 0.2835 | E29: =Sous_Detail_Prix!$E$46 -> 273288.22 | F29: =D29*E29 -> 77477.21
A30: 4 | B30: Plancher dalle pleine (plancher haut RDC) | C30: m3 | D30: =Dalle!$H$12 -> 6.89975 | E30: =Sous_Detail_Prix!$E$46 -> 273288.22 | F30: =D30*E30 -> 1885620.4
A31: 5 | B31: Plancher hourdis 12+4 (plancher haut RDC) | C31: m2 | D31: =Dalle!$G$31 -> 0 | E31: =PU_HOURDIS_12_4 -> 9500 | F31: =D31*E31 -> 0
A32: 6 | B32: Maconnerie d'agglos creux de 15 cm | C32: m2 | D32: =Elevation!$G$200 -> 79.29 | E32: =Sous_Detail_Prix!$E$69 -> 6624.8428 | F32: =D32*E32 -> 525283.79
A33: 7 | B33: Enduits (interieurs + exterieurs) | C33: m2 | D33: =Elevation!$G$200*2 -> 158.58 | E33: =Sous_Detail_Prix!$E$78 -> 1805.6 | F33: =D33*E33 -> 286332.05
A34: 8 | B34: Scellement et calfeutrement des huisseries | C34: ml | D34: =21.5 -> 21.5 | E34: =PU_SCELLEMENT_HUISSERIE -> 500 | F34: =D34*E34 -> 10750
A35: 9 | B35: Dressement des tableaux | C35: ml | D35: =21.5 -> 21.5 | E35: =PU_DRESSEMENT_TABLEAUX -> 500 | F35: =D35*E35 -> 10750
A36: Sous-total RDC | F36: =SUM(F27:F35) -> 3465223
B38: III - ETAGE 1
A39: 1 | B39: Beton arme dose a 350 kg/m3 (poteaux) | C39: m3 | D39: =Elevation!$G$194 -> 1.344 | E39: =Sous_Detail_Prix!$E$46 -> 273288.22 | F39: =D39*E39 -> 367299.37
A40: 2 | B40: Beton arme dose a 350 kg/m3 (ceinture) | C40: m3 | D40: =Elevation!$G$196 -> 1.008 | E40: =Sous_Detail_Prix!$E$46 -> 273288.22 | F40: =D40*E40 -> 275474.53
A41: 3 | B41: Beton arme dose a 350 kg/m3 (linteaux et appuis) | C41: m3 | D41: =Elevation!$G$198 -> 0.2835 | E41: =Sous_Detail_Prix!$E$46 -> 273288.22 | F41: =D41*E41 -> 77477.21
A42: 4 | B42: Beton arme dose a 350 kg/m3 (escalier) | C42: m3 | D42: =Elevation!$G$199 -> 3.5 | E42: =Sous_Detail_Prix!$E$46 -> 273288.22 | F42: =D42*E42 -> 956508.77
A43: 5 | B43: Plancher dalle pleine (plancher haut Etage 1) | C43: m3 | D43: =Dalle!$H$39 -> 0 | E43: =Sous_Detail_Prix!$E$46 -> 273288.22 | F43: =D43*E43 -> 0
A44: 6 | B44: Plancher hourdis 12+4 (plancher haut Etage 1) | C44: m2 | D44: =Dalle!$G$58 -> 68.9975 | E44: =PU_HOURDIS_12_4 -> 9500 | F44: =D44*E44 -> 655476.25
A45: 7 | B45: Maconnerie d'agglos creux de 15 cm | C45: m2 | D45: =Elevation!$G$201 -> 64.5 | E45: =Sous_Detail_Prix!$E$69 -> 6624.8428 | F45: =D45*E45 -> 427302.36
A46: 8 | B46: Enduits (interieurs + exterieurs) | C46: m2 | D46: =Elevation!$G$201*2 -> 129 | E46: =Sous_Detail_Prix!$E$78 -> 1805.6 | F46: =D46*E46 -> 232922.4
...
